<?xml version="1.0" ?>
<!-- =================================================================================== -->
<!-- |    This document was autogenerated by xacro from vx300s_7dof.urdf.xacro         | -->
<!-- |    EDITING THIS FILE BY HAND IS NOT RECOMMENDED                                 | -->
<!-- =================================================================================== -->
<robot name="vx300s">
  <material name="interbotix_black">
    <texture filename="package://vx300s_7dof_description/meshes/interbotix_black.png"/>
  </material>
  <link name="vx300s_7dof/base_link">
    <visual>
      <origin rpy="0 0 1.5707963267948966" xyz="0 0 0"/>
      <geometry>
        <mesh filename="package://vx300s_7dof_description/meshes/vx300s_1_base.stl" scale="0.001 0.001 0.001"/>
      </geometry>
      <material name="interbotix_black"/>
    </visual>
    <collision>
      <origin rpy="0 0 1.5707963267948966" xyz="0 0 0"/>
      <geometry>
        <mesh filename="package://vx300s_7dof_description/meshes/vx300s_1_base.stl" scale="0.001 0.001 0.001"/>
      </geometry>
    </collision>
    <inertial>
      <origin rpy="0 0 1.5707963267948966" xyz="-0.0534774000 -0.0005625750 0.0205961000"/>
      <mass value="0.969034"/>
      <inertia ixx="0.0060240000" ixy="0.0000471300" ixz="0.0000038510" iyy="0.0017000000" iyz="-0.0000841500" izz="0.0071620000"/>
    </inertial>
  </link>
  <joint name="waist" type="revolute">
    <axis xyz="0 0 1"/>
    <limit effort="10" lower="-3.141582653589793" upper="3.141582653589793" velocity="3.141592653589793"/>
    <origin rpy="0 0 0" xyz="0 0 0.079"/>
    <parent link="vx300s_7dof/base_link"/>
    <child link="vx300s_7dof/shoulder_link"/>
    <dynamics friction="0.1"/>
  </joint>
  <transmission name="trans_waist">
    <type>transmission_interface/SimpleTransmission</type>
    <joint name="waist">
      <hardwareInterface>hardware_interface/EffortJointInterface</hardwareInterface>
    </joint>
    <actuator name="waist_motor">
      <mechanicalReduction>1</mechanicalReduction>
    </actuator>
  </transmission>
  <link name="vx300s_7dof/shoulder_link">
    <visual>
      <origin rpy="0 0 1.5707963267948966" xyz="0 0 -0.003"/>
      <geometry>
        <mesh filename="package://vx300s_7dof_description/meshes/vx300s_2_shoulder.stl" scale="0.001 0.001 0.001"/>
      </geometry>
      <material name="interbotix_black"/>
    </visual>
    <collision>
      <origin rpy="0 0 1.5707963267948966" xyz="0 0 -0.003"/>
      <geometry>
        <mesh filename="package://vx300s_7dof_description/meshes/vx300s_2_shoulder.stl" scale="0.001 0.001 0.001"/>
      </geometry>
    </collision>
    <inertial>
      <origin rpy="0 0 1.5707963267948966" xyz="0.0002592330 -0.0000033552 0.0116129000"/>
      <mass value="0.798614"/>
      <inertia ixx="0.0009388000" ixy="-0.0000000010" ixz="-0.0000000191" iyy="0.0011380000" iyz="0.0000059568" izz="0.0012010000"/>
    </inertial>
  </link>
  <joint name="shoulder" type="revolute">
    <axis xyz="0 1 0"/>
    <limit effort="20" lower="-1.8500490071139892" upper="1.2566370614359172" velocity="3.141592653589793"/>
    <origin rpy="0 0 0" xyz="0 0 0.04805"/>
    <parent link="vx300s_7dof/shoulder_link"/>
    <child link="vx300s_7dof/upper_arm_link"/>
    <dynamics friction="0.1"/>
  </joint>
  <transmission name="trans_shoulder">
    <type>transmission_interface/SimpleTransmission</type>
    <joint name="shoulder">
      <hardwareInterface>hardware_interface/EffortJointInterface</hardwareInterface>
    </joint>
    <actuator name="shoulder_motor">
      <mechanicalReduction>1</mechanicalReduction>
    </actuator>
  </transmission>
  <link name="vx300s_7dof/upper_arm_link">
    <visual>
      <origin rpy="0 0 1.5707963267948966" xyz="0 0 0"/>
      <geometry>
        <mesh filename="package://vx300s_7dof_description/meshes/vx300s_3_upper_arm.stl" scale="0.001 0.001 0.001"/>
      </geometry>
      <material name="interbotix_black"/>
    </visual>
    <collision>
      <origin rpy="0 0 1.5707963267948966" xyz="0 0 0"/>
      <geometry>
        <mesh filename="package://vx300s_7dof_description/meshes/vx300s_3_upper_arm.stl" scale="0.001 0.001 0.001"/>
      </geometry>
    </collision>
    <inertial>
      <origin rpy="0 0 1.5707963267948966" xyz="0.0206949000 0.0000000004 0.2264590000"/>
      <mass value="0.792592"/>
      <inertia ixx="0.0089250000" ixy="0.0000000000" ixz="0.0000000000" iyy="0.0089370000" iyz="0.0012010000" izz="0.0009357000"/>
    </inertial>
  </link>
  <joint name="elbow" type="revolute">
    <axis xyz="0 1 0"/>
    <limit effort="15" lower="-1.7627825445142729" upper="1.6057029118347832" velocity="3.141592653589793"/>
    <origin rpy="0 0 0" xyz="0.05955 0 0.3"/>
    <parent link="vx300s_7dof/upper_arm_link"/>
    <child link="vx300s_7dof/upper_forearm_link"/>
    <dynamics friction="0.1"/>
  </joint>
  <transmission name="trans_elbow">
    <type>transmission_interface/SimpleTransmission</type>
    <joint name="elbow">
      <hardwareInterface>hardware_interface/EffortJointInterface</hardwareInterface>
    </joint>
    <actuator name="elbow_motor">
      <mechanicalReduction>1</mechanicalReduction>
    </actuator>
  </transmission>
  <link name="vx300s_7dof/upper_forearm_link">
    <visual>
      <origin rpy="0 0 0" xyz="0 0 0"/>
      <geometry>
        <mesh filename="package://vx300s_7dof_description/meshes/vx300s_4_upper_forearm.stl" scale="0.001 0.001 0.001"/>
      </geometry>
      <material name="interbotix_black"/>
    </visual>
    <collision>
      <origin rpy="0 0 0" xyz="0 0 0"/>
      <geometry>
        <mesh filename="package://vx300s_7dof_description/meshes/vx300s_4_upper_forearm.stl" scale="0.001 0.001 0.001"/>
      </geometry>
    </collision>
    <inertial>
      <origin rpy="0 0 0" xyz="0.105723 0 0"/>
      <mass value="0.322228"/>
      <inertia ixx="0.0001524000" ixy="-0.0000188300" ixz="-0.0000084064" iyy="0.0013420000" iyz="0.0000012564" izz="0.0014410000"/>
    </inertial>
  </link>
  <joint name="forearm_roll" type="revolute">
    <axis xyz="1 0 0"/>
    <limit effort="2" lower="-3.141582653589793" upper="3.141582653589793" velocity="3.141592653589793"/>
    <origin rpy="0 0 0" xyz="0.2 0 0"/>
    <parent link="vx300s_7dof/upper_forearm_link"/>
    <child link="vx300s_7dof/lower_forearm_link"/>
    <dynamics friction="0.1"/>
  </joint>
  <transmission name="trans_forearm_roll">
    <type>transmission_interface/SimpleTransmission</type>
    <joint name="forearm_roll">
      <hardwareInterface>hardware_interface/EffortJointInterface</hardwareInterface>
    </joint>
    <actuator name="forearm_roll_motor">
      <mechanicalReduction>1</mechanicalReduction>
    </actuator>
  </transmission>
  <link name="vx300s_7dof/lower_forearm_link">
    <visual>
      <origin rpy="3.141592653589793 0 0" xyz="0 0 0"/>
      <geometry>
        <mesh filename="package://vx300s_7dof_description/meshes/vx300s_5_lower_forearm.stl" scale="0.001 0.001 0.001"/>
      </geometry>
      <material name="interbotix_black"/>
    </visual>
    <collision>
      <origin rpy="3.141592653589793 0 0" xyz="0 0 0"/>
      <geometry>
        <mesh filename="package://vx300s_7dof_description/meshes/vx300s_5_lower_forearm.stl" scale="0.001 0.001 0.001"/>
      </geometry>
    </collision>
    <inertial>
      <origin rpy="3.141592653589793 0 0" xyz="0.0513477000 0.0068046200 0"/>
      <mass value="0.414823"/>
      <inertia ixx="0.0001753000" ixy="-0.0000852800" ixz="0" iyy="0.0005269000" iyz="0" izz="0.0005911000"/>
    </inertial>
  </link>
  <joint name="wrist_1_joint" type="revolute">
    <axis xyz="1 0 0"/>
    <limit effort="5" lower="-1.8675022996339325" upper="2.234021442552742" velocity="3.141592653589793"/>
    <origin rpy="0 0 1.5707963267948966" xyz="0.1 0 0"/>
    <parent link="vx300s_7dof/lower_forearm_link"/>
    <child link="vx300s_7dof/wrist_1_link"/>
    <dynamics friction="0.1"/>
  </joint>
  <transmission name="trans_wrist_angle">
    <type>transmission_interface/SimpleTransmission</type>
    <joint name="wrist_angle">
      <hardwareInterface>hardware_interface/EffortJointInterface</hardwareInterface>
    </joint>
    <actuator name="wrist_angle_motor">
      <mechanicalReduction>1</mechanicalReduction>
    </actuator>
  </transmission>
  <link name="vx300s_7dof/wrist_1_link">
    <visual>
      <origin rpy="0 0 0" xyz="0 0 0"/>
      <geometry>
        <mesh filename="package://vx300s_7dof_description/meshes/vx300s_7dof_wrist_1.stl" scale="0.001 0.001 0.001"/>
      </geometry>
      <material name="interbotix_black"/>
    </visual>
    <collision>
      <origin rpy="0 0 0" xyz="0 0 0"/>
      <geometry>
        <mesh filename="package://vx300s_7dof_description/meshes/vx300s_7dof_wrist_1.stl" scale="0.001 0.001 0.001"/>
      </geometry>
    </collision>
    <inertial>
      <origin rpy="0 0 0" xyz="-0.00016056389157290035 -0.04783644576268217 0.011114667243825252"/>
      <mass value="0.11539500000052595"/>
      <inertia ixx="4.197327507711e-05" ixy="-0.0" ixz="-0.0" iyy="4.197327507711e-05" iyz="3.22871346747e-06" izz="4.520198854458e-05"/>
    </inertial>
  </link>
  <link name="vx300s_7dof/wrist_2_link">
    <inertial>
      <origin rpy="0 0 0" xyz="4.3609031555899395e-07 -0.02330839051358337 0.0056858689583885414"/>
      <mass value="0.09999999999793989"/>
      <inertia ixx="3.40818535776e-05" ixy="-0.0" ixz="0.0" iyy="2.9821621880399998e-05" iyz="-3.5501930809999996e-07" izz="4.43774135125e-05"/>
    </inertial>
    <visual>
      <origin rpy="0 0 0" xyz="0.000161 0.07 0.0"/>
      <geometry>
        <mesh filename="package://vx300s_7dof_description/meshes/vx300s_7dof_wrist_2.stl" scale="0.001 0.001 0.001"/>
      </geometry>
      <material name="interbotix_black"/>
    </visual>
    <collision>
      <origin rpy="0 0 0" xyz="0.000161 0.07 0.0"/>
      <geometry>
        <mesh filename="package://vx300s_7dof_description/meshes/vx300s_7dof_wrist_2.stl" scale="0.001 0.001 0.001"/>
      </geometry>
    </collision>
  </link>
  <joint name="wrist_2_joint" type="revolute">
    <axis xyz="0 -1 0"/>
    <limit effort="5" lower="-3.141582653589793" upper="3.141582653589793" velocity="3.141592653589793"/>
    <origin rpy="0 0 0" xyz="-0.000161 -0.07 0.0"/>
    <parent link="vx300s_7dof/wrist_1_link"/>
    <child link="vx300s_7dof/wrist_2_link"/>
    <dynamics friction="0.1"/>
  </joint>
  <link name="vx300s_7dof/wrist_3_link">
    <inertial>
      <origin rpy="0 0 0" xyz="0.006991739511968901 0.00431837142418863 -0.01147389409196783"/>
      <mass value="0.019999999999826944"/>
      <inertia ixx="1.3688306707e-06" ixy="-2.7376613414e-07" ixz="1.3688306707e-07" iyy="8.62363322541e-06" iyz="0.0" izz="8.76051629248e-06"/>
    </inertial>
    <visual>
      <origin rpy="0 0 0" xyz="0.000161 0.11125 0.01325"/>
      <geometry>
        <mesh filename="package://vx300s_7dof_description/meshes/vx300s_7dof_wrist_3.stl" scale="0.001 0.001 0.001"/>
      </geometry>
      <material name="interbotix_black"/>
    </visual>
    <collision>
      <origin rpy="0 0 0" xyz="0.000161 0.11125 0.01325"/>
      <geometry>
        <mesh filename="package://vx300s_7dof_description/meshes/vx300s_7dof_wrist_3.stl" scale="0.001 0.001 0.001"/>
      </geometry>
    </collision>
  </link>
  <joint name="wrist_3_joint" type="revolute">
    <origin rpy="0 3.141592653589793 3.141592653589793" xyz="0.0 -0.04125 0.02475"/>
    <limit effort="5" lower="-3.141582653589793" upper="3.141582653589793" velocity="3.141592653589793"/>
    <parent link="vx300s_7dof/wrist_2_link"/>
    <child link="vx300s_7dof/wrist_3_link"/>
    <axis xyz="-0.0 -0.0 1.0"/>
    <dynamics friction="0.1"/>
  </joint>
  <link name="vx300s_7dof/camera_attach_link"/>
  <joint name="camera_attach_joint" type="fixed">
    <origin rpy="3.141592653589793 0 1.5707963267948966" xyz="0 0.0011925388 -0.03"/>
    <parent link="vx300s_7dof/wrist_3_link"/>
    <child link="vx300s_7dof/camera_attach_link"/>
  </joint>
  <material name="zedm_mat">
    <color rgba="0.3 0.3 0.3 1.0"/>
  </material>
  <!-- Camera mounting point (the threaded screw hole in the bottom) -->
  <link name="zed_base_link">
    <collision>
      <origin rpy="0 0 0" xyz="0 0 0"/>
      <geometry>
        <box size="0.03 0.03 0.03"/>
      </geometry>
    </collision>
  </link>
  <joint name="zed_base_joint" type="fixed">
    <parent link="vx300s_7dof/camera_attach_link"/>
    <child link="zed_base_link"/>
    <origin rpy="0 0 0" xyz="0 0 0"/>
  </joint>
  <!-- Camera Center -->
  <link name="zed_camera_center">
    <visual>
      <origin rpy="0 0 0" xyz="0.0 0 0.0"/>
      <geometry>
        <mesh filename="package://vx300s_7dof_description/meshes/zedm.stl"/>
      </geometry>
      <material name="zedm_mat"/>
    </visual>
    <collision>
      <geometry>
        <mesh filename="package://vx300s_7dof_description/meshes/zedm.stl"/>
      </geometry>
    </collision>
  </link>
  <joint name="zed_camera_center_joint" type="fixed">
    <parent link="zed_base_link"/>
    <child link="zed_camera_center"/>
    <origin rpy="0 0.0 0" xyz="0 0 0.01325"/>
  </joint>
  <!-- Left Camera -->
  <link name="zed_left_camera_frame">
    <collision>
      <origin rpy="0 0 0" xyz="0 0 0"/>
      <geometry>
        <box size="0.03 0.03 0.03"/>
      </geometry>
    </collision>
  </link>
  <joint name="zed_left_camera_joint" type="fixed">
    <parent link="zed_camera_center"/>
    <child link="zed_left_camera_frame"/>
    <origin rpy="0 0 0" xyz="0.0 0.03 0"/>
  </joint>
  <link name="zed_left_camera_optical_frame">
    <collision>
      <origin rpy="0 0 0" xyz="0 0 0"/>
      <geometry>
        <box size="0.03 0.03 0.03"/>
      </geometry>
    </collision>
  </link>
  <joint name="zed_left_camera_optical_joint" type="fixed">
    <origin rpy="-1.5707963267948966 0.0 -1.5707963267948966" xyz="0 0 0"/>
    <parent link="zed_left_camera_frame"/>
    <child link="zed_left_camera_optical_frame"/>
  </joint>
  <!-- Right Camera -->
  <link name="zed_right_camera_frame">
    <collision>
      <origin rpy="0 0 0" xyz="0 0 0"/>
      <geometry>
        <box size="0.03 0.03 0.03"/>
      </geometry>
    </collision>
  </link>
  <joint name="zed_right_camera_joint" type="fixed">
    <parent link="zed_camera_center"/>
    <child link="zed_right_camera_frame"/>
    <origin rpy="0 0 0" xyz="0.0 -0.03 0"/>
  </joint>
  <link name="zed_right_camera_optical_frame">
    <collision>
      <origin rpy="0 0 0" xyz="0 0 0"/>
      <geometry>
        <box size="0.03 0.03 0.03"/>
      </geometry>
    </collision>
  </link>
  <joint name="zed_right_camera_optical_joint" type="fixed">
    <origin rpy="-1.5707963267948966 0.0 -1.5707963267948966" xyz="0 0 0"/>
    <parent link="zed_right_camera_frame"/>
    <child link="zed_right_camera_optical_frame"/>
  </joint>
</robot>

